Workbook

Sheet Summary
A1: Summary
A2: Effort days per difficulty are my rough estimates for one developer. Edit columns B–C (blue) and every effort figure updates. Totals count only features not yet done (see Status below).
A4: Difficulty | B4: Effort low (days) | C4: Effort high (days) | D4: Open features | E4: Total low (days) | F4: Total high (days) | G4: Meaning
A5: Easy | B5: 0.5 | C5: 1 | D5: =COUNTIFS('Feature gaps'!$F$5:$F$65,A5,'Feature gaps'!$K$5:$K$65,"<>Done") | E5: =SUMIFS('Feature gaps'!$G$5:$G$65,'Feature gaps'!$F$5:$F$65,A5,'Feature gaps'!$K$5:$K$65,"<>Done") | F5: =SUMIFS('Feature gaps'!$H$5:$H$65,'Feature gaps'!$F$5:$F$65,A5,'Feature gaps'!$K$5:$K$65,"<>Done") | G5: About a day or less
A6: Easy–Medium | B6: 1 | C6: 3 | D6: =COUNTIFS('Feature gaps'!$F$5:$F$65,A6,'Feature gaps'!$K$5:$K$65,"<>Done") | E6: =SUMIFS('Feature gaps'!$G$5:$G$65,'Feature gaps'!$F$5:$F$65,A6,'Feature gaps'!$K$5:$K$65,"<>Done") | F6: =SUMIFS('Feature gaps'!$H$5:$H$65,'Feature gaps'!$F$5:$F$65,A6,'Feature gaps'!$K$5:$K$65,"<>Done") | G6: One to three days
A7: Medium | B7: 2 | C7: 5 | D7: =COUNTIFS('Feature gaps'!$F$5:$F$65,A7,'Feature gaps'!$K$5:$K$65,"<>Done") | E7: =SUMIFS('Feature gaps'!$G$5:$G$65,'Feature gaps'!$F$5:$F$65,A7,'Feature gaps'!$K$5:$K$65,"<>Done") | F7: =SUMIFS('Feature gaps'!$H$5:$H$65,'Feature gaps'!$F$5:$F$65,A7,'Feature gaps'!$K$5:$K$65,"<>Done") | G7: A few days
A8: Medium–Hard | B8: 5 | C8: 10 | D8: =COUNTIFS('Feature gaps'!$F$5:$F$65,A8,'Feature gaps'!$K$5:$K$65,"<>Done") | E8: =SUMIFS('Feature gaps'!$G$5:$G$65,'Feature gaps'!$F$5:$F$65,A8,'Feature gaps'!$K$5:$K$65,"<>Done") | F8: =SUMIFS('Feature gaps'!$H$5:$H$65,'Feature gaps'!$F$5:$F$65,A8,'Feature gaps'!$K$5:$K$65,"<>Done") | G8: One to two weeks
A9: Hard | B9: 5 | C9: 15 | D9: =COUNTIFS('Feature gaps'!$F$5:$F$65,A9,'Feature gaps'!$K$5:$K$65,"<>Done") | E9: =SUMIFS('Feature gaps'!$G$5:$G$65,'Feature gaps'!$F$5:$F$65,A9,'Feature gaps'!$K$5:$K$65,"<>Done") | F9: =SUMIFS('Feature gaps'!$H$5:$H$65,'Feature gaps'!$F$5:$F$65,A9,'Feature gaps'!$K$5:$K$65,"<>Done") | G9: One to three weeks
A10: Very hard | B10: 15 | C10: 30 | D10: =COUNTIFS('Feature gaps'!$F$5:$F$65,A10,'Feature gaps'!$K$5:$K$65,"<>Done") | E10: =SUMIFS('Feature gaps'!$G$5:$G$65,'Feature gaps'!$F$5:$F$65,A10,'Feature gaps'!$K$5:$K$65,"<>Done") | F10: =SUMIFS('Feature gaps'!$H$5:$H$65,'Feature gaps'!$F$5:$F$65,A10,'Feature gaps'!$K$5:$K$65,"<>Done") | G10: More than three weeks, or depends on outside approval
A11: Not applicable | B11: 0 | C11: 0 | D11: =COUNTIFS('Feature gaps'!$F$5:$F$65,A11,'Feature gaps'!$K$5:$K$65,"<>Done") | E11: =SUMIFS('Feature gaps'!$G$5:$G$65,'Feature gaps'!$F$5:$F$65,A11,'Feature gaps'!$K$5:$K$65,"<>Done") | F11: =SUMIFS('Feature gaps'!$H$5:$H$65,'Feature gaps'!$F$5:$F$65,A11,'Feature gaps'!$K$5:$K$65,"<>Done") | G11: Not practical in a standalone app
A12: Total | D12: =SUM(D5:D11) | E12: =SUM(E5:E11) | F12: =SUM(F5:F11)
A14: Suggested priority | B14: What it covers | D14: Open features | E14: Total low (days) | F14: Total high (days)
A15: 1 | B15: Data compatibility: the add-on's reminders behave the same (all done in 0.2.5) | D15: =COUNTIFS('Feature gaps'!$J$5:$J$65,A15,'Feature gaps'!$K$5:$K$65,"<>Done") | E15: =SUMIFS('Feature gaps'!$G$5:$G$65,'Feature gaps'!$J$5:$J$65,A15,'Feature gaps'!$K$5:$K$65,"<>Done") | F15: =SUMIFS('Feature gaps'!$H$5:$H$65,'Feature gaps'!$J$5:$J$65,A15,'Feature gaps'!$K$5:$K$65,"<>Done")
A16: 2 | B16: Quick wins: Quick Alarm, suspend, snooze until, repeat sound, restore backup, go to date (all done in 0.3.0) | D16: =COUNTIFS('Feature gaps'!$J$5:$J$65,A16,'Feature gaps'!$K$5:$K$65,"<>Done") | E16: =SUMIFS('Feature gaps'!$G$5:$G$65,'Feature gaps'!$J$5:$J$65,A16,'Feature gaps'!$K$5:$K$65,"<>Done") | F16: =SUMIFS('Feature gaps'!$H$5:$H$65,'Feature gaps'!$J$5:$J$65,A16,'Feature gaps'!$K$5:$K$65,"<>Done")
A17: 3 | B17: Printing and calendar subscriptions | D17: =COUNTIFS('Feature gaps'!$J$5:$J$65,A17,'Feature gaps'!$K$5:$K$65,"<>Done") | E17: =SUMIFS('Feature gaps'!$G$5:$G$65,'Feature gaps'!$J$5:$J$65,A17,'Feature gaps'!$K$5:$K$65,"<>Done") | F17: =SUMIFS('Feature gaps'!$H$5:$H$65,'Feature gaps'!$J$5:$J$65,A17,'Feature gaps'!$K$5:$K$65,"<>Done")
A18: 4 | B18: CalDAV sync | D18: =COUNTIFS('Feature gaps'!$J$5:$J$65,A18,'Feature gaps'!$K$5:$K$65,"<>Done") | E18: =SUMIFS('Feature gaps'!$G$5:$G$65,'Feature gaps'!$J$5:$J$65,A18,'Feature gaps'!$K$5:$K$65,"<>Done") | F18: =SUMIFS('Feature gaps'!$H$5:$H$65,'Feature gaps'!$J$5:$J$65,A18,'Feature gaps'!$K$5:$K$65,"<>Done")
A19: Later | B19: Everything else, including the proposed Thunderbird email scanning | D19: =COUNTIFS('Feature gaps'!$J$5:$J$65,A19,'Feature gaps'!$K$5:$K$65,"<>Done") | E19: =SUMIFS('Feature gaps'!$G$5:$G$65,'Feature gaps'!$J$5:$J$65,A19,'Feature gaps'!$K$5:$K$65,"<>Done") | F19: =SUMIFS('Feature gaps'!$H$5:$H$65,'Feature gaps'!$J$5:$J$65,A19,'Feature gaps'!$K$5:$K$65,"<>Done")
A20: — | B20: Not applicable | D20: =COUNTIFS('Feature gaps'!$J$5:$J$65,A20,'Feature gaps'!$K$5:$K$65,"<>Done") | E20: =SUMIFS('Feature gaps'!$G$5:$G$65,'Feature gaps'!$J$5:$J$65,A20,'Feature gaps'!$K$5:$K$65,"<>Done") | F20: =SUMIFS('Feature gaps'!$H$5:$H$65,'Feature gaps'!$J$5:$J$65,A20,'Feature gaps'!$K$5:$K$65,"<>Done")
A22: Status | D22: Features
A23: Not started | D23: =COUNTIF('Feature gaps'!$K$5:$K$65,A23)
A24: Planned | D24: =COUNTIF('Feature gaps'!$K$5:$K$65,A24)
A25: In progress | D25: =COUNTIF('Feature gaps'!$K$5:$K$65,A25)
A26: Done | D26: =COUNTIF('Feature gaps'!$K$5:$K$65,A26)
A27: Won't do | D27: =COUNTIF('Feature gaps'!$K$5:$K$65,A27)
A29: Source | D29: Features | E29: Done | F29: Open | G29: Open effort, low – high (days)
A30: In ReminderFox 2.1.6 | D30: =COUNTIF('Feature gaps'!$C$5:$C$65,A30) | E30: =COUNTIFS('Feature gaps'!$C$5:$C$65,A30,'Feature gaps'!$K$5:$K$65,"Done") | F30: =D30-E30 | G30: =TEXT(SUMIFS('Feature gaps'!$G$5:$G$65,'Feature gaps'!$C$5:$C$65,A30,'Feature gaps'!$K$5:$K$65,"<>Done"),"0.0")&" – "&TEXT(SUMIFS('Feature gaps'!$H$5:$H$65,'Feature gaps'!$C$5:$C$65,A30,'Feature gaps'!$K$5:$K$65,"<>Done"),"0")
A31: New (not in the add-on) | D31: =COUNTIF('Feature gaps'!$C$5:$C$65,A31) | E31: =COUNTIFS('Feature gaps'!$C$5:$C$65,A31,'Feature gaps'!$K$5:$K$65,"Done") | F31: =D31-E31 | G31: =TEXT(SUMIFS('Feature gaps'!$G$5:$G$65,'Feature gaps'!$C$5:$C$65,A31,'Feature gaps'!$K$5:$K$65,"<>Done"),"0.0")&" – "&TEXT(SUMIFS('Feature gaps'!$H$5:$H$65,'Feature gaps'!$C$5:$C$65,A31,'Feature gaps'!$K$5:$K$65,"<>Done"),"0")
A32: Total | D32: =D30+D31 | E32: =E30+E31 | F32: =F30+F31
A33: In ReminderFox 2.1.6: the add-on had it (ReminderFoxAgain may have it now, or not yet). New: not in the add-on, whether proposed, requested or already added.

Sheet Feature gaps
A1: The original ReminderFox add-on (2.1.6) and ReminderFoxAgain 0.9.1 — ReminderFox's features still to bring across, and new features (proposed or added)
A2: With thanks to ReminderFox's creators, Tom Mutdosch and Daniel Lee, with Guenter Wahl (github.com/tommut/reminderfox). Difficulty and effort days are estimates for one developer (see the Summary tab). The Source column says whether a feature was in the ReminderFox 2.1.6 add-on or is new. Yellow columns are yours to fill in.
A4: # | B4: Area | C4: Source | D4: Feature | E4: Current app (0.9.1) | F4: Difficulty | G4: Effort low (days) | H4: Effort high (days) | I4: Notes / approach | J4: Suggested priority | K4: Status | L4: Owner / comments
A5: 1 | B5: Data the add-on writes that the current app ignores | C5: In ReminderFox 2.1.6 | D5: Remind daily until completed: an overdue reminder keeps showing as today, and keeps alarming, until ticked | E5: Done in 0.2.5 | F5: Easy–Medium | G5: =IFERROR(INDEX(Summary!$B$5:$B$11,MATCH(F5,Summary!$A$5:$A$11,0)),"") | H5: =IFERROR(INDEX(Summary!$C$5:$C$11,MATCH(F5,Summary!$A$5:$A$11,0)),"") | I5: Checkbox in the editor; the alarm check treats unticked past occurrences as due today. Stored as X-REMINDERFOX-REMIND-UNTIL-COMPLETED (used on Mom's birthday in the sample file). | J5: 1 | K5: Done | L5: Implemented in 0.2.5
A6: 2 | B6: Data the add-on writes that the current app ignores | C6: In ReminderFox 2.1.6 | D6: Age and anniversary numbers in titles: "Mom's birthday <1960>" shows how many years it has been; <1960#> is a variant | E6: Done in 0.2.5 | F6: Easy | G6: =IFERROR(INDEX(Summary!$B$5:$B$11,MATCH(F6,Summary!$A$5:$A$11,0)),"") | H6: =IFERROR(INDEX(Summary!$C$5:$C$11,MATCH(F6,Summary!$A$5:$A$11,0)),"") | I6: Text substitution when displaying the title. | J6: 1 | K6: Done | L6: Implemented in 0.2.5
A7: 3 | B7: Data the add-on writes that the current app ignores | C7: In ReminderFox 2.1.6 | D7: Show in tooltip: per-item flag (mainly to-dos) to list it in the toolbar icon's tooltip | E7: Done in 0.2.5 | F7: Easy | G7: =IFERROR(INDEX(Summary!$B$5:$B$11,MATCH(F7,Summary!$A$5:$A$11,0)),"") | H7: =IFERROR(INDEX(Summary!$C$5:$C$11,MATCH(F7,Summary!$A$5:$A$11,0)),"") | I7: Stored as X-REMINDERFOX-SHOW-IN-TOOLTIP. | J7: 1 | K7: Done | L7: Implemented in 0.2.5
A8: 4 | B8: Data the add-on writes that the current app ignores | C8: In ReminderFox 2.1.6 | D8: Open the email a reminder came from (Thunderbird) | E8: Ignored | F8: Not applicable | G8: =IFERROR(INDEX(Summary!$B$5:$B$11,MATCH(F8,Summary!$A$5:$A$11,0)),"") | H8: =IFERROR(INDEX(Summary!$C$5:$C$11,MATCH(F8,Summary!$A$5:$A$11,0)),"") | I8: Stored as X-REMINDERFOX-MESSAGEID; only meaningful inside Thunderbird. | J8: — | K8: Not started
A9: 5 | B9: Alarms and notifications | C9: In ReminderFox 2.1.6 | D9: Quick Alarm: a one-off "in 20 minutes" or "at 3:00" alarm with a message, without making a reminder | E9: Done in 0.3.0 | F9: Easy | G9: =IFERROR(INDEX(Summary!$B$5:$B$11,MATCH(F9,Summary!$A$5:$A$11,0)),"") | H9: =IFERROR(INDEX(Summary!$C$5:$C$11,MATCH(F9,Summary!$A$5:$A$11,0)),"") | I9: Toolbar button, Ctrl+Q and tray menu; in N minutes/hours/days or at a time; waiting list with Cancel. | J9: — | K9: Done | L9: Implemented in 0.3.0
A10: 6 | B10: Alarms and notifications | C10: In ReminderFox 2.1.6 | D10: Suspend alerts and alarms until resumed, or for a set time | E10: Done in 0.3.0 | F10: Easy | G10: =IFERROR(INDEX(Summary!$B$5:$B$11,MATCH(F10,Summary!$A$5:$A$11,0)),"") | H10: =IFERROR(INDEX(Summary!$C$5:$C$11,MATCH(F10,Summary!$A$5:$A$11,0)),"") | I10: Until resumed, for a time, or until a date and time; status bar shows it and resumes on click. | J10: — | K10: Done | L10: Implemented in 0.3.0
A11: 7 | B11: Alarms and notifications | C11: In ReminderFox 2.1.6 | D11: Snooze until a specific time | E11: Done in 0.3.0 | F11: Easy | G11: =IFERROR(INDEX(Summary!$B$5:$B$11,MATCH(F11,Summary!$A$5:$A$11,0)),"") | H11: =IFERROR(INDEX(Summary!$C$5:$C$11,MATCH(F11,Summary!$A$5:$A$11,0)),"") | I11: "until…" in the alarm window: 15:30, 3:30 pm, 3pm (earlier than now = tomorrow). | J11: — | K11: Done | L11: Implemented in 0.3.0
A12: 8 | B12: Alarms and notifications | C12: In ReminderFox 2.1.6 | D12: Repeat the alarm sound every N minutes until acknowledged | E12: Done in 0.3.0 | F12: Easy | G12: =IFERROR(INDEX(Summary!$B$5:$B$11,MATCH(F12,Summary!$A$5:$A$11,0)),"") | H12: =IFERROR(INDEX(Summary!$C$5:$C$11,MATCH(F12,Summary!$A$5:$A$11,0)),"") | I12: Every 1–15 minutes until the alarm is dealt with. | J12: — | K12: Done | L12: Implemented in 0.3.0
A13: 9 | B13: Alarms and notifications | C13: In ReminderFox 2.1.6 | D13: Custom alarm sound file | E13: Done in 0.3.0 | F13: Easy–Medium | G13: =IFERROR(INDEX(Summary!$B$5:$B$11,MATCH(F13,Summary!$A$5:$A$11,0)),"") | H13: =IFERROR(INDEX(Summary!$C$5:$C$11,MATCH(F13,Summary!$A$5:$A$11,0)),"") | I13: Copied into the data folder; Test button; back to the chime in one click. | J13: — | K13: Done | L13: Implemented in 0.3.0
A14: 10 | B14: Alarms and notifications | C14: In ReminderFox 2.1.6 | D14: Alert slider: corner pop-up listing today's and upcoming reminders every N minutes, with a choice of corner | E14: Done in 0.3.0 | F14: Medium | G14: =IFERROR(INDEX(Summary!$B$5:$B$11,MATCH(F14,Summary!$A$5:$A$11,0)),"") | H14: =IFERROR(INDEX(Summary!$C$5:$C$11,MATCH(F14,Summary!$A$5:$A$11,0)),"") | I14: Reminder pop-up: corner, how often, how long, sound; click an item to open it. | J14: — | K14: Done | L14: Implemented in 0.3.0
A15: 11 | B15: Alarms and notifications | C15: In ReminderFox 2.1.6 | D15: Count badge on the toolbar icon (today's and upcoming items) | E15: Done in 0.3.0 | F15: Easy–Medium | G15: =IFERROR(INDEX(Summary!$B$5:$B$11,MATCH(F15,Summary!$A$5:$A$11,0)),"") | H15: =IFERROR(INDEX(Summary!$C$5:$C$11,MATCH(F15,Summary!$A$5:$A$11,0)),"") | I15: Tray and taskbar icons; today's or today's and upcoming open items. | J15: — | K15: Done | L15: Implemented in 0.3.0
A16: 12 | B16: Lists, views and display | C16: In ReminderFox 2.1.6 | D16: Custom lists as their own tabs, for reminders as well as to-dos, with "Move to list" | E16: Done in 0.3.0 | F16: Medium | G16: =IFERROR(INDEX(Summary!$B$5:$B$11,MATCH(F16,Summary!$A$5:$A$11,0)),"") | H16: =IFERROR(INDEX(Summary!$C$5:$C$11,MATCH(F16,Summary!$A$5:$A$11,0)),"") | I16: To-do lists with counts; manage lists (add/rename/merge/reorder/remove); Move to list…; a reminder can be made a to-do. Since 0.6.0 they are picked in the Lists tab's dropdown (as in the add-on's list menu) instead of one tab each. Separate reminder lists were not added (the add-on kept reminders in one list too in most setups). | J16: — | K16: Done | L16: Implemented in 0.3.0
A17: 13 | B17: Lists, views and display | C17: In ReminderFox 2.1.6 | D17: Views: saved filters built from criteria (text, category, date range, etc.) with an editor | E17: Done in 0.3.0 | F17: Medium–Hard | G17: =IFERROR(INDEX(Summary!$B$5:$B$11,MATCH(F17,Summary!$A$5:$A$11,0)),"") | H17: =IFERROR(INDEX(Summary!$C$5:$C$11,MATCH(F17,Summary!$A$5:$A$11,0)),"") | I17: View editor with conditions (any/description/category/notes/location), relative date range, optional to-dos; same matching rules as the add-on. | J17: — | K17: Done | L17: Implemented in 0.3.0
A18: 14 | B18: Lists, views and display | C18: In ReminderFox 2.1.6 | D18: Repeating-reminder display: show N previous or upcoming occurrences, hide repeating reminders, hide completed items | E18: Done in 0.3.0 | F18: Easy–Medium | G18: =IFERROR(INDEX(Summary!$B$5:$B$11,MATCH(F18,Summary!$A$5:$A$11,0)),"") | H18: =IFERROR(INDEX(Summary!$C$5:$C$11,MATCH(F18,Summary!$A$5:$A$11,0)),"") | I18: Show the next 1–10 or all of the year's occurrences; hide repeating; hide completed. Since 0.3.1 past occurrences (ticked or not) are listed as in the calendar; since 0.3.3 every list with future dates projects the repeats (Settings → Lists). | J18: — | K18: Done | L18: Implemented in 0.3.0
A19: 15 | B19: Lists, views and display | C19: In ReminderFox 2.1.6 | D19: Manual to-do order (move up and down) | E19: Done in 0.3.0 | F19: Medium | G19: =IFERROR(INDEX(Summary!$B$5:$B$11,MATCH(F19,Summary!$A$5:$A$11,0)),"") | H19: =IFERROR(INDEX(Summary!$C$5:$C$11,MATCH(F19,Summary!$A$5:$A$11,0)),"") | I19: My order: drag rows or Alt+↑/↓; stored as X-APPLE-SORT-ORDER. | J19: — | K19: Done | L19: Implemented in 0.3.0
A20: 16 | B20: Lists, views and display | C20: In ReminderFox 2.1.6 | D20: Category manager: rename or delete a category across all items, keep a default category list | E20: Done in 0.3.0 | F20: Medium | G20: =IFERROR(INDEX(Summary!$B$5:$B$11,MATCH(F20,Summary!$A$5:$A$11,0)),"") | H20: =IFERROR(INDEX(Summary!$C$5:$C$11,MATCH(F20,Summary!$A$5:$A$11,0)),"") | I20: Rename/merge, delete from items, add own or common categories; tick-list picker in the editor. | J20: — | K20: Done | L20: Implemented in 0.3.0
... A24: 20 | B24: Lists, views and display | C24: In ReminderFox 2.1.6 | D24: "Show map" button for a location | E24: Done in 0.3.0 | F24: Easy | G24: =IFERROR(INDEX(Summary!$B$5:$B$11,MATCH(F24,Summary!$A$5:$A$11,0)),"") | H24: =IFERROR(INDEX(Summary!$C$5:$C$11,MATCH(F24,Summary!$A$5:$A$11,0)),"") | I24: Editor 🗺 and right-click; Google Maps, OpenStreetMap or Bing. | J24: — | K24: Done | L24: Implemented in 0.3.0
A25: 21 | B25: Printing | C25: In ReminderFox 2.1.6 | D25: Print / view all or selected events, or a daily Agenda, with editable templates; agenda can open at start-up | E25: None | F25: Medium | G25: =IFERROR(INDEX(Summary!$B$5:$B$11,MATCH(F25,Summary!$A$5:$A$11,0)),"") | H25: =IFERROR(INDEX(Summary!$C$5:$C$11,MATCH(F25,Summary!$A$5:$A$11,0)),"") | I25: Medium for built-in layouts (print or save as PDF); Hard if users can edit the templates. | J25: 3 | K25: Not started
A26: 22 | B26: Import, backup and sync | C26: In ReminderFox 2.1.6 | D26: Back up now / restore from a backup in the app | E26: Done in 0.3.0 | F26: Easy | G26: =IFERROR(INDEX(Summary!$B$5:$B$11,MATCH(F26,Summary!$A$5:$A$11,0)),"") | H26: =IFERROR(INDEX(Summary!$C$5:$C$11,MATCH(F26,Summary!$A$5:$A$11,0)),"") | I26: Back up now, save a copy, restore from any backup with a safety copy first (restore can be undone). | J26: — | K26: Done | L26: Implemented in 0.3.0
A27: 23 | B27: Import, backup and sync | C27: In ReminderFox 2.1.6 | D27: Import choices: overwrite or start a new calendar, give imported items a category, detect duplicates | E27: Done in 0.7.0 | F27: Easy–Medium | G27: =IFERROR(INDEX(Summary!$B$5:$B$11,MATCH(F27,Summary!$A$5:$A$11,0)),"") | H27: =IFERROR(INDEX(Summary!$C$5:$C$11,MATCH(F27,Summary!$A$5:$A$11,0)),"") | I27: Every import opens a dialog showing what the file holds: Add to what I have or Replace everything (what you have is saved as a backup first, restorable from Settings → Data); skip items with the same title and date as one you have, or import them anyway; an optional category added to every imported item. Same-ID items still merge, the newer copy winning. | J27: — | K27: Done | L27: Implemented in 0.7.0
A28: 24 | B28: Import, backup and sync | C28: In ReminderFox 2.1.6 | D28: Subscribe to a calendar by URL (holidays, sports, etc.), read-only and refreshed regularly | E28: None | F28: Medium | G28: =IFERROR(INDEX(Summary!$B$5:$B$11,MATCH(F28,Summary!$A$5:$A$11,0)),"") | H28: =IFERROR(INDEX(Summary!$C$5:$C$11,MATCH(F28,Summary!$A$5:$A$11,0)),"") | J28: 3 | K28: Not started
A29: 25 | B29: Import, backup and sync | C29: In ReminderFox 2.1.6 | D29: Sync the file through an FTP or web server | E29: None | F29: Medium | G29: =IFERROR(INDEX(Summary!$B$5:$B$11,MATCH(F29,Summary!$A$5:$A$11,0)),"") | H29: =IFERROR(INDEX(Summary!$C$5:$C$11,MATCH(F29,Summary!$A$5:$A$11,0)),"") | I29: Web server (WebDAV) is easier than FTP; needs conflict handling. | J29: Later | K29: Not started
A30: 26 | B30: Import, backup and sync | C30: In ReminderFox 2.1.6 | D30: CalDAV sync with servers like fruux, Nextcloud/ownCloud or Radicale, including per-account colours | E30: None | F30: Hard | G30: =IFERROR(INDEX(Summary!$B$5:$B$11,MATCH(F30,Summary!$A$5:$A$11,0)),"") | H30: =IFERROR(INDEX(Summary!$C$5:$C$11,MATCH(F30,Summary!$A$5:$A$11,0)),"") | I30: The biggest remaining gap for people who used the add-on with Nextcloud or fruux. | J30: 4 | K30: Not started
A31: 27 | B31: Import, backup and sync | C31: In ReminderFox 2.1.6 | D31: Google Calendar and Google Tasks sync | E31: None | F31: Very hard | G31: =IFERROR(INDEX(Summary!$B$5:$B$11,MATCH(F31,Summary!$A$5:$A$11,0)),"") | H31: =IFERROR(INDEX(Summary!$C$5:$C$11,MATCH(F31,Summary!$A$5:$A$11,0)),"") | I31: OAuth plus Google's app-verification process; Tasks uses its own API. | J31: Later | K31: Not started
A32: 28 | B32: Email and browser integration (Firefox/Thunderbird only) | C32: In ReminderFox 2.1.6 | D32: Send reminders or to-dos by email, and invitations with attendees and accept/decline | E32: Export to a file only | F32: Medium | G32: =IFERROR(INDEX(Summary!$B$5:$B$11,MATCH(F32,Summary!$A$5:$A$11,0)),"") | H32: =IFERROR(INDEX(Summary!$C$5:$C$11,MATCH(F32,Summary!$A$5:$A$11,0)),"") | I32: Medium to send an .ics by email; Hard for real invitations and replies. | J32: Later | K32: Not started
A33: 29 | B33: Email and browser integration (Firefox/Thunderbird only) | C33: In ReminderFox 2.1.6 | D33: Reminder from an email, "Send++" (send a mail and create a follow-up), message tagging, address-book autocomplete | E33: None | F33: Not applicable | G33: =IFERROR(INDEX(Summary!$B$5:$B$11,MATCH(F33,Summary!$A$5:$A$11,0)),"") | H33: =IFERROR(INDEX(Summary!$C$5:$C$11,MATCH(F33,Summary!$A$5:$A$11,0)),"") | I33: Not practical in the app alone. The proposed Thunderbird add-on (see the "Thunderbird email scanning" rows) would cover creating reminders from email; Send++ and tagging would still need more work. | J33: — | K33: Not started
A34: 30 | B34: Email and browser integration (Firefox/Thunderbird only) | C34: In ReminderFox 2.1.6 | D34: Birthday reminders from address-book contacts | E34: None | F34: Medium | G34: =IFERROR(INDEX(Summary!$B$5:$B$11,MATCH(F34,Summary!$A$5:$A$11,0)),"") | H34: =IFERROR(INDEX(Summary!$C$5:$C$11,MATCH(F34,Summary!$A$5:$A$11,0)),"") | I34: If imported from a vCard or CSV export. | J34: Later | K34: Not started
A35: 31 | B35: Email and browser integration (Firefox/Thunderbird only) | C35: In ReminderFox 2.1.6 | D35: Right-click "Add reminder" on a web page or selected text; subscribe to an .ics link | E35: None | F35: Hard | G35: =IFERROR(INDEX(Summary!$B$5:$B$11,MATCH(F35,Summary!$A$5:$A$11,0)),"") | H35: =IFERROR(INDEX(Summary!$C$5:$C$11,MATCH(F35,Summary!$A$5:$A$11,0)),"") | I35: Needs a companion browser extension. An "Add from clipboard" button would be Easy. | J35: Later | K35: Not started
A36: 32 | B36: Thunderbird email scanning | C36: New (not in the add-on) | D36: Thunderbird add-on that passes each new email (sender, subject, date, body, attachments) to ReminderFoxAgain | E36: None | F36: Medium | G36: =IFERROR(INDEX(Summary!$B$5:$B$11,MATCH(F36,Summary!$A$5:$A$11,0)),"") | H36: =IFERROR(INDEX(Summary!$C$5:$C$11,MATCH(F36,Summary!$A$5:$A$11,0)),"") | I36: Uses Thunderbird's "native messaging" channel; the installer registers the app. Only sees mail while Thunderbird is running. | J36: Later | K36: Not started
A37: 33 | B37: Thunderbird email scanning | C37: New (not in the add-on) | D37: "From your email" suggestion list: Accept / Edit / Ignore; updates shown before-and-after; optional auto-accept for chosen senders | E37: None | F37: Medium | G37: =IFERROR(INDEX(Summary!$B$5:$B$11,MATCH(F37,Summary!$A$5:$A$11,0)),"") | H37: =IFERROR(INDEX(Summary!$C$5:$C$11,MATCH(F37,Summary!$A$5:$A$11,0)),"") | I37: The scanner only suggests; nothing is changed or deleted without you. | J37: Later | K37: Not started
A38: 34 | B38: Thunderbird email scanning | C38: New (not in the add-on) | D38: Link each reminder to its email, with an "Open email" button that jumps back to the message in Thunderbird | E38: None | F38: Easy | G38: =IFERROR(INDEX(Summary!$B$5:$B$11,MATCH(F38,Summary!$A$5:$A$11,0)),"") | H38: =IFERROR(INDEX(Summary!$C$5:$C$11,MATCH(F38,Summary!$A$5:$A$11,0)),"") | I38: ReminderFox's own X-REMINDERFOX-MESSAGEID property already holds this link. | J38: Later | K38: Not started
A39: 35 | B39: Thunderbird email scanning | C39: New (not in the add-on) | D39: Read calendar invitations (.ics): new invite creates, change updates, cancellation suggests deleting, matched by the invite's ID | E39: Manual import only | F39: Easy–Medium | G39: =IFERROR(INDEX(Summary!$B$5:$B$11,MATCH(F39,Summary!$A$5:$A$11,0)),"") | H39: =IFERROR(INDEX(Summary!$C$5:$C$11,MATCH(F39,Summary!$A$5:$A$11,0)),"") | I39: Exact, no guessing. | J39: Later | K39: Not started
A40: 36 | B40: Thunderbird email scanning | C40: New (not in the add-on) | D40: Read the structured data in airline, hotel, ticket and delivery emails | E40: None | F40: Easy–Medium | G40: =IFERROR(INDEX(Summary!$B$5:$B$11,MATCH(F40,Summary!$A$5:$A$11,0)),"") | H40: =IFERROR(INDEX(Summary!$C$5:$C$11,MATCH(F40,Summary!$A$5:$A$11,0)),"") | I40: Exact, no guessing. | J40: Later | K40: Not started
... A44: 40 | B44: Thunderbird email scanning | C44: New (not in the add-on) | D44: Test set of real emails to tune the rules and prompts and catch mistakes | E44: None | F44: Medium | G44: =IFERROR(INDEX(Summary!$B$5:$B$11,MATCH(F44,Summary!$A$5:$A$11,0)),"") | H44: =IFERROR(INDEX(Summary!$C$5:$C$11,MATCH(F44,Summary!$A$5:$A$11,0)),"") | I44: Guards against invented dates, time-zone mix-ups and misleading email text. Try the rules first, then add the model for what they miss. | J44: Later | K44: Not started
A45: 41 | B45: Requested additions | C45: New (not in the add-on) | D45: Archive: keep expired or no-longer-valid reminders and to-dos for reference, out of the lists; move them back and forth easily | E45: Done in 0.2.6 | F45: Medium | G45: =IFERROR(INDEX(Summary!$B$5:$B$11,MATCH(F45,Summary!$A$5:$A$11,0)),"") | H45: =IFERROR(INDEX(Summary!$C$5:$C$11,MATCH(F45,Summary!$A$5:$A$11,0)),"") | I45: Added in 0.2.6 as a separate archive.ics with an Archive tab. Replaced in 0.6.0 by an ordinary list, "Terminated or Suspended": the Archive tab is gone, and anything left in an old archive moves onto that list on start (a backup of the archive is kept). | J45: — | K45: Done | L45: Implemented in 0.2.6
A46: 42 | B46: Requested additions | C46: New (not in the add-on) | D46: Past reminders in the list: completed and uncompleted, repeating or one-time, as the calendar shows them | E46: Done in 0.3.1 | F46: Easy–Medium | G46: =IFERROR(INDEX(Summary!$B$5:$B$11,MATCH(F46,Summary!$A$5:$A$11,0)),"") | H46: =IFERROR(INDEX(Summary!$C$5:$C$11,MATCH(F46,Summary!$A$5:$A$11,0)),"") | I46: Extends the add-on's "show N previous occurrences": All reminders and Past list every past occurrence, ticked or not; Settings → Lists sets how far back repeats go. | J46: — | K46: Done | L46: Implemented in 0.3.1
A47: 43 | B47: Requested additions | C47: New (not in the add-on) | D47: Plan ahead: future repeating reminders projected from their repeat rules, in every list with future dates | E47: Done in 0.3.3 | F47: Medium | G47: =IFERROR(INDEX(Summary!$B$5:$B$11,MATCH(F47,Summary!$A$5:$A$11,0)),"") | H47: =IFERROR(INDEX(Summary!$C$5:$C$11,MATCH(F47,Summary!$A$5:$A$11,0)),"") | I47: Extends the add-on's "show N upcoming occurrences": Upcoming (0.3.2), then All, Important, search and views (0.3.3); month headings count their reminders; how far ahead in Settings → Lists. The separate Plan ahead list was folded into Upcoming in 0.3.4. | J47: — | K47: Done | L47: Implemented in 0.3.3
...

Sheet Current app extras
A1: What ReminderFoxAgain 0.9.1 adds alongside ReminderFox's features
A3: # | B3: Area | C3: Feature
A4: 1 | B4: Independence | C4: Runs on its own as a desktop app, carrying ReminderFox's ideas forward outside the browser.
A5: 2 | B5: Calendar standards | C5: Proper time-zone handling; items from Google or Outlook keep any data the app doesn't understand.
A6: 3 | B6: Completion history | C6: Ticking one occurrence of a repeating reminder records when you did it.
A7: 4 | B7: Data safety | C7: Automatic daily backups; an unreadable file is never overwritten.
A8: 5 | B8: Display | C8: Month grid, six themes (incl. high contrast), starred items in their own colour.
A9: 6 | B9: To-dos | C9: A due-by date with repeating "remind me" reminders until it's done, and one step to turn it into a dated reminder.
A10: 7 | B10: Planning | C10: Future repeats projected in every list, with counts per month; past occurrences listed ticked or not.
A11: 8 | B11: Calendar view | C11: Completed list items stay in their list but leave the Month view, the mini calendar and the agenda (0.7.0); the Month view's Show completed brings them back (0.8.0).
A12: 9 | B12: Your layout | C12: Choose the columns of the Reminders tab and the lists, order lists by any column, and pick one of five alarm sounds, repeated continuously if you like (0.8.0).
A13: 10 | B13: Your look | C13: Make your own themes from five colours, with a live preview and contrast warnings (0.8.1).
A14: 11 | B14: Platforms | C14: Windows, macOS (one app for Apple silicon and Intel) and Linux (.deb and .tar.gz) from one source, each with its own wording, shortcuts and menus (0.9.0).
A15: 12 | B15: Installer and tests | C15: A per-user installer with checksums and rollback, identical builds, and automated tests (unit, UI, installer).
